Traceback (most recent call last):
  File "/home/frmuno/anaconda3/envs/jupyterbook/lib/python3.8/site-packages/nbclient/client.py", line 627, in _async_poll_for_reply
    msg = await ensure_async(self.kc.shell_channel.get_msg(timeout=new_timeout))
  File "/home/frmuno/anaconda3/envs/jupyterbook/lib/python3.8/site-packages/nbclient/util.py", line 89, in ensure_async
    result = await obj
  File "/home/frmuno/anaconda3/envs/jupyterbook/lib/python3.8/site-packages/jupyter_client/channels.py", line 230, in get_msg
    raise Empty
_queue.Empty

During handling of the above exception, another exception occurred:

Traceback (most recent call last):
  File "/home/frmuno/anaconda3/envs/jupyterbook/lib/python3.8/site-packages/jupyter_cache/executors/utils.py", line 51, in single_nb_execution
    executenb(
  File "/home/frmuno/anaconda3/envs/jupyterbook/lib/python3.8/site-packages/nbclient/client.py", line 1117, in execute
    return NotebookClient(nb=nb, resources=resources, km=km, **kwargs).execute()
  File "/home/frmuno/anaconda3/envs/jupyterbook/lib/python3.8/site-packages/nbclient/util.py", line 78, in wrapped
    return just_run(coro(*args, **kwargs))
  File "/home/frmuno/anaconda3/envs/jupyterbook/lib/python3.8/site-packages/nbclient/util.py", line 57, in just_run
    return loop.run_until_complete(coro)
  File "/home/frmuno/anaconda3/envs/jupyterbook/lib/python3.8/asyncio/base_events.py", line 616, in run_until_complete
    return future.result()
  File "/home/frmuno/anaconda3/envs/jupyterbook/lib/python3.8/site-packages/nbclient/client.py", line 558, in async_execute
    await self.async_execute_cell(
  File "/home/frmuno/anaconda3/envs/jupyterbook/lib/python3.8/site-packages/nbclient/client.py", line 846, in async_execute_cell
    exec_reply = await self.task_poll_for_reply
  File "/home/frmuno/anaconda3/envs/jupyterbook/lib/python3.8/site-packages/nbclient/client.py", line 651, in _async_poll_for_reply
    await self._async_handle_timeout(timeout, cell)
  File "/home/frmuno/anaconda3/envs/jupyterbook/lib/python3.8/site-packages/nbclient/client.py", line 701, in _async_handle_timeout
    raise CellTimeoutError.error_from_timeout_and_cell(
nbclient.exceptions.CellTimeoutError: A cell timed out while it was being executed, after 30 seconds.
The message was: Cell execution timed out.
Here is a preview of the cell contents:
-------------------
from urllib.request import urlopen
import xml.etree.ElementTree as ET

l13_ini_url = 'https://app.parlamento.pt/webutils/docs/doc.xml?path=6148523063446f764c324679626d56304c3239775a57356b595852684c3052685a47397a51574a6c636e52766379394a626d6c6a6157463061585a686379395953556c4a4a5449775447566e61584e7359585231636d45765357357059326c6864476c3259584e5953556c4a4c6e687462413d3d&fich=IniciativasXIII.xml&Inline=true'
l13_ini_tree = ET.parse(urlopen(l13_ini_url))

l14_ini_url = ''
-------------------

