Traceback (most recent call last):
  File "/home/frmuno/anaconda3/envs/jupyterbook/lib/python3.8/site-packages/jupyter_cache/executors/utils.py", line 51, in single_nb_execution
    executenb(
  File "/home/frmuno/anaconda3/envs/jupyterbook/lib/python3.8/site-packages/nbclient/client.py", line 1112, in execute
    return NotebookClient(nb=nb, resources=resources, km=km, **kwargs).execute()
  File "/home/frmuno/anaconda3/envs/jupyterbook/lib/python3.8/site-packages/nbclient/util.py", line 74, in wrapped
    return just_run(coro(*args, **kwargs))
  File "/home/frmuno/anaconda3/envs/jupyterbook/lib/python3.8/site-packages/nbclient/util.py", line 53, in just_run
    return loop.run_until_complete(coro)
  File "/home/frmuno/anaconda3/envs/jupyterbook/lib/python3.8/asyncio/base_events.py", line 616, in run_until_complete
    return future.result()
  File "/home/frmuno/anaconda3/envs/jupyterbook/lib/python3.8/site-packages/nbclient/client.py", line 553, in async_execute
    await self.async_execute_cell(
  File "/home/frmuno/anaconda3/envs/jupyterbook/lib/python3.8/site-packages/nbclient/client.py", line 857, in async_execute_cell
    self._check_raise_for_error(cell, exec_reply)
  File "/home/frmuno/anaconda3/envs/jupyterbook/lib/python3.8/site-packages/nbclient/client.py", line 760, in _check_raise_for_error
    raise CellExecutionError.from_cell_and_msg(cell, exec_reply_content)
nbclient.exceptions.CellExecutionError: An error occurred while executing the following cell:
------------------
from sklearn.manifold import MDS
import random

sns.set()
sns.set_style("ticks")


fig, ax = plt.subplots(figsize=(8,8))

fig.suptitle('Portuguese Parliament Voting Records Analysis, 13th Legislature', fontsize=14)
ax.set_title('MDS with DBSCAN clusters (2D)')

for label, x, y in zip(distmat_mm.columns, coords[:, 0], coords[:, 1]):
    ax.scatter(x, y, c = "C"+str(dbscan_dict[label]+3), s=250)
    ax.axis('equal')
    ax.annotate(label,xy = (x-0.02, y+0.025))

plt.show()
------------------

[0;31m---------------------------------------------------------------------------[0m
[0;31mNameError[0m                                 Traceback (most recent call last)
[0;32m/tmp/ipykernel_49415/1446680498.py[0m in [0;36m<module>[0;34m[0m
[1;32m     11[0m [0max[0m[0;34m.[0m[0mset_title[0m[0;34m([0m[0;34m'MDS with DBSCAN clusters (2D)'[0m[0;34m)[0m[0;34m[0m[0;34m[0m[0m
[1;32m     12[0m [0;34m[0m[0m
[0;32m---> 13[0;31m [0;32mfor[0m [0mlabel[0m[0;34m,[0m [0mx[0m[0;34m,[0m [0my[0m [0;32min[0m [0mzip[0m[0;34m([0m[0mdistmat_mm[0m[0;34m.[0m[0mcolumns[0m[0;34m,[0m [0mcoords[0m[0;34m[[0m[0;34m:[0m[0;34m,[0m [0;36m0[0m[0;34m][0m[0;34m,[0m [0mcoords[0m[0;34m[[0m[0;34m:[0m[0;34m,[0m [0;36m1[0m[0;34m][0m[0;34m)[0m[0;34m:[0m[0;34m[0m[0;34m[0m[0m
[0m[1;32m     14[0m     [0max[0m[0;34m.[0m[0mscatter[0m[0;34m([0m[0mx[0m[0;34m,[0m [0my[0m[0;34m,[0m [0mc[0m [0;34m=[0m [0;34m"C"[0m[0;34m+[0m[0mstr[0m[0;34m([0m[0mdbscan_dict[0m[0;34m[[0m[0mlabel[0m[0;34m][0m[0;34m+[0m[0;36m3[0m[0;34m)[0m[0;34m,[0m [0ms[0m[0;34m=[0m[0;36m250[0m[0;34m)[0m[0;34m[0m[0;34m[0m[0m
[1;32m     15[0m     [0max[0m[0;34m.[0m[0maxis[0m[0;34m([0m[0;34m'equal'[0m[0;34m)[0m[0;34m[0m[0;34m[0m[0m

[0;31mNameError[0m: name 'coords' is not defined
NameError: name 'coords' is not defined

