Traceback (most recent call last):
  File "/home/frmuno/anaconda3/envs/jupyterbook/lib/python3.8/site-packages/jupyter_cache/executors/utils.py", line 51, in single_nb_execution
    executenb(
  File "/home/frmuno/anaconda3/envs/jupyterbook/lib/python3.8/site-packages/nbclient/client.py", line 1112, in execute
    return NotebookClient(nb=nb, resources=resources, km=km, **kwargs).execute()
  File "/home/frmuno/anaconda3/envs/jupyterbook/lib/python3.8/site-packages/nbclient/util.py", line 74, in wrapped
    return just_run(coro(*args, **kwargs))
  File "/home/frmuno/anaconda3/envs/jupyterbook/lib/python3.8/site-packages/nbclient/util.py", line 53, in just_run
    return loop.run_until_complete(coro)
  File "/home/frmuno/anaconda3/envs/jupyterbook/lib/python3.8/asyncio/base_events.py", line 616, in run_until_complete
    return future.result()
  File "/home/frmuno/anaconda3/envs/jupyterbook/lib/python3.8/site-packages/nbclient/client.py", line 553, in async_execute
    await self.async_execute_cell(
  File "/home/frmuno/anaconda3/envs/jupyterbook/lib/python3.8/site-packages/nbclient/client.py", line 857, in async_execute_cell
    self._check_raise_for_error(cell, exec_reply)
  File "/home/frmuno/anaconda3/envs/jupyterbook/lib/python3.8/site-packages/nbclient/client.py", line 760, in _check_raise_for_error
    raise CellExecutionError.from_cell_and_msg(cell, exec_reply_content)
nbclient.exceptions.CellExecutionError: An error occurred while executing the following cell:
------------------
from datetime import datetime
from IPython.display import display, Markdown, Latex


display(Markdown("*Total de vota√ß√µes:* {}".format(votes.shape[0])))
display(Markdown("*Data limite inferior:* {}".format(datetime.date(min_date))))
display(Markdown("*Data limite superior:* {}".format(datetime.date(max_date))))


------------------

[0;31m---------------------------------------------------------------------------[0m
[0;31mTypeError[0m                                 Traceback (most recent call last)
[0;32m/tmp/ipykernel_553849/3562492761.py[0m in [0;36m<module>[0;34m[0m
[1;32m      4[0m [0;34m[0m[0m
[1;32m      5[0m [0mdisplay[0m[0;34m([0m[0mMarkdown[0m[0;34m([0m[0;34m"*Total de vota√ß√µes:* {}"[0m[0;34m.[0m[0mformat[0m[0;34m([0m[0mvotes[0m[0;34m.[0m[0mshape[0m[0;34m[[0m[0;36m0[0m[0;34m][0m[0;34m)[0m[0;34m)[0m[0;34m)[0m[0;34m[0m[0;34m[0m[0m
[0;32m----> 6[0;31m [0mdisplay[0m[0;34m([0m[0mMarkdown[0m[0;34m([0m[0;34m"*Data limite inferior:* {}"[0m[0;34m.[0m[0mformat[0m[0;34m([0m[0mdatetime[0m[0;34m.[0m[0mdate[0m[0;34m([0m[0mmin_date[0m[0;34m)[0m[0;34m)[0m[0;34m)[0m[0;34m)[0m[0;34m[0m[0;34m[0m[0m
[0m[1;32m      7[0m [0mdisplay[0m[0;34m([0m[0mMarkdown[0m[0;34m([0m[0;34m"*Data limite superior:* {}"[0m[0;34m.[0m[0mformat[0m[0;34m([0m[0mdatetime[0m[0;34m.[0m[0mdate[0m[0;34m([0m[0mmax_date[0m[0;34m)[0m[0;34m)[0m[0;34m)[0m[0;34m)[0m[0;34m[0m[0;34m[0m[0m
[1;32m      8[0m [0;34m[0m[0m

[0;31mTypeError[0m: descriptor 'date' for 'datetime.datetime' objects doesn't apply to a 'str' object
TypeError: descriptor 'date' for 'datetime.datetime' objects doesn't apply to a 'str' object

